Workbook

Sheet 2019-10-16T1414_Grades-MGT_404_
A1: Student | B1: ID | C1: SIS User ID | D1: SIS Login ID | E1: Root Account | F1: Section | G1: Problem Set 1 (129587) | H1: Problem Set 2 (125489) | I1: Problem Set 3 (125490) | J1: Final Exam (125495) | K1: Participation | L1: Final | M1: Final (No NA) | N1: Grade
Q2: Min Score | R2: Count | S2: Pct
A3: Points Possible | G3: 10 | H3: 10 | I3: 10 | J3: 180 | K3: 10 | P3: HH | Q3: 91.333333 | R3: =COUNTIF($N$4:$N$361,P3) -> 34 | S3: =R3/SUM($R$3:$R$6) -> 0.10271903
A4: Agarwal, Vibhav | B4: 87811 | C4: 17547995 | D4: va256 | E4: yale.instructure.com | F4: MGT 404 01 | G4: 0 | J4: =VLOOKUP(C4,exam!$D$29:$V$359,19,0) -> #N/A | K4: 10 | L4: =SUM(K4,I4,H4,G4)+J4/3 -> #N/A | M4: =IF(ISERROR(L4),"",L4) | N4: =IF(M4="","",IF(M4>=$Q$3,$P$3,IF(M4>=$Q$4,$P$4,IF(M4>=$Q$5,$P$5,"P")))) | P4: H | Q4: 85.225 | R4: =COUNTIF($N$4:$N$361,P4) -> 83 | S4: =R4/SUM($R$3:$R$6) -> 0.25075529
A5: Alon, Kfir | B5: 107576 | C5: 24086292 | D5: ka527 | E5: yale.instructure.com | F5: MGT 404 01 | G5: 9 | H5: 9.75 | I5: 9.6 | J5: =VLOOKUP(C5,exam!$D$29:$V$359,19,0) -> 88.5 | K5: 10 | L5: =SUM(K5,I5,H5,G5)+J5/3 -> 67.85 | M5: =IF(ISERROR(L5),"",L5) -> 67.85 | N5: =IF(M5="","",IF(M5>=$Q$3,$P$3,IF(M5>=$Q$4,$P$4,IF(M5>=$Q$5,$P$5,"P")))) -> P | P5: PR | Q5: 68.333333 | R5: =COUNTIF($N$4:$N$361,P5) -> 185 | S5: =R5/SUM($R$3:$R$6) -> 0.55891239
A6: Alton, Jake | B6: 107186 | C6: 24079883 | D6: jba53 | E6: yale.instructure.com | F6: MGT 404 01 | G6: 6 | H6: 9.25 | I6: 9 | J6: =VLOOKUP(C6,exam!$D$29:$V$359,19,0) -> 102.5 | K6: 10 | L6: =SUM(K6,I6,H6,G6)+J6/3 -> 68.416667 | M6: =IF(ISERROR(L6),"",L6) -> 68.416667 | N6: =IF(M6="","",IF(M6>=$Q$3,$P$3,IF(M6>=$Q$4,$P$4,IF(M6>=$Q$5,$P$5,"P")))) -> PR | P6: P | R6: =COUNTIF($N$4:$N$361,P6) -> 29 | S6: =R6/SUM($R$3:$R$6) -> 0.087613293
A7: Aslam, Fazail | B7: 113866 | C7: 24182002 | D7: fa344 | E7: yale.instructure.com | F7: MGT 404 01 | G7: 8 | H7: 10 | I7: 10 | J7: =VLOOKUP(C7,exam!$D$29:$V$359,19,0) -> 106 | K7: 10 | L7: =SUM(K7,I7,H7,G7)+J7/3 -> 73.333333 | M7: =IF(ISERROR(L7),"",L7) -> 73.333333 | N7: =IF(M7="","",IF(M7>=$Q$3,$P$3,IF(M7>=$Q$4,$P$4,IF(M7>=$Q$5,$P$5,"P")))) -> PR | P7: F | R7: =COUNTIF($N$4:$N$361,P7) -> 2 | S7: =R7/SUM($R$3:$R$6) -> 0.0060422961
A8: Bandyopadhyay, Arkadeep | B8: 103880 | C8: 24037026 | D8: ab3233 | E8: yale.instructure.com | F8: MGT 404 01 | G8: 10 | H8: 10 | I8: 9.6 | J8: =VLOOKUP(C8,exam!$D$29:$V$359,19,0) -> 156 | K8: 10 | L8: =SUM(K8,I8,H8,G8)+J8/3 -> 91.6 | M8: =IF(ISERROR(L8),"",L8) -> 91.6 | N8: =IF(M8="","",IF(M8>=$Q$3,$P$3,IF(M8>=$Q$4,$P$4,IF(M8>=$Q$5,$P$5,"P")))) -> HH
A9: Berry, Marisa | B9: 103838 | C9: 24036006 | D9: mab375 | E9: yale.instructure.com | F9: MGT 404 01 | G9: 10 | H9: 9 | I9: 10 | J9: =VLOOKUP(C9,exam!$D$29:$V$359,19,0) -> 104.5 | K9: 10 | L9: =SUM(K9,I9,H9,G9)+J9/3 -> 73.833333 | M9: =IF(ISERROR(L9),"",L9) -> 73.833333 | N9: =IF(M9="","",IF(M9>=$Q$3,$P$3,IF(M9>=$Q$4,$P$4,IF(M9>=$Q$5,$P$5,"P")))) -> PR
A10: Blazuk, Andrew | B10: 104189 | C10: 24035955 | D10: acb237 | E10: yale.instructure.com | F10: MGT 404 01 | G10: 10 | H10: 9 | I10: 10 | J10: =VLOOKUP(C10,exam!$D$29:$V$359,19,0) -> 109.5 | K10: 10 | L10: =SUM(K10,I10,H10,G10)+J10/3 -> 75.5 | M10: =IF(ISERROR(L10),"",L10) -> 75.5 | N10: =IF(M10="","",IF(M10>=$Q$3,$P$3,IF(M10>=$Q$4,$P$4,IF(M10>=$Q$5,$P$5,"P")))) -> PR
A11: Bosch, Lukas | B11: 111738 | C11: 24151232 | D11: lfb35 | E11: yale.instructure.com | F11: MGT 404 01 | G11: 10 | H11: 10 | I11: 10 | J11: =VLOOKUP(C11,exam!$D$29:$V$359,19,0) -> 154.5 | K11: 10 | L11: =SUM(K11,I11,H11,G11)+J11/3 -> 91.5 | M11: =IF(ISERROR(L11),"",L11) -> 91.5 | N11: =IF(M11="","",IF(M11>=$Q$3,$P$3,IF(M11>=$Q$4,$P$4,IF(M11>=$Q$5,$P$5,"P")))) -> HH
A12: Briggi, Danny | B12: 91806 | C12: 17595782 | D12: db2263 | E12: yale.instructure.com | F12: MGT 404 01 | G12: 0 | I12: 0 | J12: =VLOOKUP(C12,exam!$D$29:$V$359,19,0) -> #N/A | K12: 10 | L12: =SUM(K12,I12,H12,G12)+J12/3 -> #N/A | M12: =IF(ISERROR(L12),"",L12) | N12: =IF(M12="","",IF(M12>=$Q$3,$P$3,IF(M12>=$Q$4,$P$4,IF(M12>=$Q$5,$P$5,"P"))))
A13: Brody, Clare | B13: 110923 | C13: 13405066 | D13: cwb5 | E13: yale.instructure.com | F13: MGT 404 01 | G13: 9 | H13: 8.75 | I13: 10 | J13: =VLOOKUP(C13,exam!$D$29:$V$359,19,0) -> 115.5 | K13: 10 | L13: =SUM(K13,I13,H13,G13)+J13/3 -> 76.25 | M13: =IF(ISERROR(L13),"",L13) -> 76.25 | N13: =IF(M13="","",IF(M13>=$Q$3,$P$3,IF(M13>=$Q$4,$P$4,IF(M13>=$Q$5,$P$5,"P")))) -> PR
A14: Camponogara, Ivan | B14: 107954 | C14: 24092871 | D14: ic326 | E14: yale.instructure.com | F14: MGT 404 01 | G14: 10 | H14: 10 | I14: 10 | J14: =VLOOKUP(C14,exam!$D$29:$V$359,19,0) -> 159 | K14: 10 | L14: =SUM(K14,I14,H14,G14)+J14/3 -> 93 | M14: =IF(ISERROR(L14),"",L14) -> 93 | N14: =IF(M14="","",IF(M14>=$Q$3,$P$3,IF(M14>=$Q$4,$P$4,IF(M14>=$Q$5,$P$5,"P")))) -> HH
A15: Carlson, Ripley | B15: 104456 | C15: 24036601 | D15: rjc83 | E15: yale.instructure.com | F15: MGT 404 01 | G15: 9.5 | H15: 10 | I15: 9.8 | J15: =VLOOKUP(C15,exam!$D$29:$V$359,19,0) -> 150 | K15: 10 | L15: =SUM(K15,I15,H15,G15)+J15/3 -> 89.3 | M15: =IF(ISERROR(L15),"",L15) -> 89.3 | N15: =IF(M15="","",IF(M15>=$Q$3,$P$3,IF(M15>=$Q$4,$P$4,IF(M15>=$Q$5,$P$5,"P")))) -> H
A16: Chang, Julie | B16: 110277 | C16: 24129370 | D16: hc739 | E16: yale.instructure.com | F16: MGT 404 01 | G16: 10 | H16: 9.25 | I16: 10 | J16: =VLOOKUP(C16,exam!$D$29:$V$359,19,0) -> 150.5 | K16: 10 | L16: =SUM(K16,I16,H16,G16)+J16/3 -> 89.416667 | M16: =IF(ISERROR(L16),"",L16) -> 89.416667 | N16: =IF(M16="","",IF(M16>=$Q$3,$P$3,IF(M16>=$Q$4,$P$4,IF(M16>=$Q$5,$P$5,"P")))) -> H
A17: Chen, Melissa | B17: 104572 | C17: 24036295 | D17: mc3278 | E17: yale.instructure.com | F17: MGT 404 01 | G17: 9 | H17: 9 | I17: 9 | J17: =VLOOKUP(C17,exam!$D$29:$V$359,19,0) -> 137.5 | K17: 10 | L17: =SUM(K17,I17,H17,G17)+J17/3 -> 82.833333 | M17: =IF(ISERROR(L17),"",L17) -> 82.833333 | N17: =IF(M17="","",IF(M17>=$Q$3,$P$3,IF(M17>=$Q$4,$P$4,IF(M17>=$Q$5,$P$5,"P")))) -> PR
A18: Cheng, Louis | B18: 104377 | C18: 24036533 | D18: yc754 | E18: yale.instructure.com | F18: MGT 404 01 | G18: 8.5 | H18: 10 | I18: 10 | J18: =VLOOKUP(C18,exam!$D$29:$V$359,19,0) -> 146 | K18: 10 | L18: =SUM(K18,I18,H18,G18)+J18/3 -> 87.166667 | M18: =IF(ISERROR(L18),"",L18) -> 87.166667 | N18: =IF(M18="","",IF(M18>=$Q$3,$P$3,IF(M18>=$Q$4,$P$4,IF(M18>=$Q$5,$P$5,"P")))) -> H
A19: Chow, Shawn | B19: 113500 | C19: 24176494 | D19: wc558 | E19: yale.instructure.com | F19: MGT 404 01 | G19: 10 | H19: 10 | I19: 10 | J19: =VLOOKUP(C19,exam!$D$29:$V$359,19,0) -> 161.5 | K19: 10 | L19: =SUM(K19,I19,H19,G19)+J19/3 -> 93.833333 | M19: =IF(ISERROR(L19),"",L19) -> 93.833333 | N19: =IF(M19="","",IF(M19>=$Q$3,$P$3,IF(M19>=$Q$4,$P$4,IF(M19>=$Q$5,$P$5,"P")))) -> HH
A20: Cichon, Norbert | B20: 112481 | C20: 24162928 | D20: nnc8 | E20: yale.instructure.com | F20: MGT 404 01 | G20: 9.5 | H20: 10 | I20: 10 | J20: =VLOOKUP(C20,exam!$D$29:$V$359,19,0) -> 131.5 | K20: 10 | L20: =SUM(K20,I20,H20,G20)+J20/3 -> 83.333333 | M20: =IF(ISERROR(L20),"",L20) -> 83.333333 | N20: =IF(M20="","",IF(M20>=$Q$3,$P$3,IF(M20>=$Q$4,$P$4,IF(M20>=$Q$5,$P$5,"P")))) -> PR
A21: Cisneros, Tony | B21: 82127 | C21: 17469744 | D21: ac2764 | E21: yale.instructure.com | F21: MGT 404 01 | G21: 0 | I21: 0 | J21: =VLOOKUP(C21,exam!$D$29:$V$359,19,0) -> #N/A | K21: 10 | L21: =SUM(K21,I21,H21,G21)+J21/3 -> #N/A | M21: =IF(ISERROR(L21),"",L21) | N21: =IF(M21="","",IF(M21>=$Q$3,$P$3,IF(M21>=$Q$4,$P$4,IF(M21>=$Q$5,$P$5,"P"))))
A22: Dai, Tina | B22: 58424 | C22: 17221765 | D22: md2289 | E22: yale.instructure.com | F22: MGT 404 01 | G22: 6.5 | H22: 9 | I22: 10 | J22: =VLOOKUP(C22,exam!$D$29:$V$359,19,0) -> 131 | K22: 10 | L22: =SUM(K22,I22,H22,G22)+J22/3 -> 79.166667 | M22: =IF(ISERROR(L22),"",L22) -> 79.166667 | N22: =IF(M22="","",IF(M22>=$Q$3,$P$3,IF(M22>=$Q$4,$P$4,IF(M22>=$Q$5,$P$5,"P")))) -> PR
A23: de Barros Carvalho Longo, Bruno | B23: 111175 | C23: 24143769 | D23: bdl33 | E23: yale.instructure.com | F23: MGT 404 01 | G23: 9 | H23: 10 | I23: 10 | J23: =VLOOKUP(C23,exam!$D$29:$V$359,19,0) -> 117.5 | K23: 10 | L23: =SUM(K23,I23,H23,G23)+J23/3 -> 78.166667 | M23: =IF(ISERROR(L23),"",L23) -> 78.166667 | N23: =IF(M23="","",IF(M23>=$Q$3,$P$3,IF(M23>=$Q$4,$P$4,IF(M23>=$Q$5,$P$5,"P")))) -> PR
A24: Desai, Keval | B24: 17638 | C24: 15880589 | D24: knd22 | E24: yale.instructure.com | F24: MGT 404 01 | G24: 0 | I24: 0 | J24: =VLOOKUP(C24,exam!$D$29:$V$359,19,0) -> #N/A | K24: 10 | L24: =SUM(K24,I24,H24,G24)+J24/3 -> #N/A | M24: =IF(ISERROR(L24),"",L24) | N24: =IF(M24="","",IF(M24>=$Q$3,$P$3,IF(M24>=$Q$4,$P$4,IF(M24>=$Q$5,$P$5,"P"))))
A25: Desien, Nick | B25: 103988 | C25: 24035717 | D25: ncd37 | E25: yale.instructure.com | F25: MGT 404 01 | G25: 9.5 | H25: 10 | I25: 10 | J25: =VLOOKUP(C25,exam!$D$29:$V$359,19,0) -> 151.5 | K25: 10 | L25: =SUM(K25,I25,H25,G25)+J25/3 -> 90 | M25: =IF(ISERROR(L25),"",L25) -> 90 | N25: =IF(M25="","",IF(M25>=$Q$3,$P$3,IF(M25>=$Q$4,$P$4,IF(M25>=$Q$5,$P$5,"P")))) -> H
A26: Doshi, Pooja | B26: 82016 | C26: 17469812 | D26: prd26 | E26: yale.instructure.com | F26: MGT 404 01 | G26: 0 | I26: 0 | J26: =VLOOKUP(C26,exam!$D$29:$V$359,19,0) -> #N/A | K26: 10 | L26: =SUM(K26,I26,H26,G26)+J26/3 -> #N/A | M26: =IF(ISERROR(L26),"",L26) | N26: =IF(M26="","",IF(M26>=$Q$3,$P$3,IF(M26>=$Q$4,$P$4,IF(M26>=$Q$5,$P$5,"P"))))
A27: Edelman, AJ | B27: 111140 | C27: 24143684 | D27: aje46 | E27: yale.instructure.com | F27: MGT 404 01 | G27: 9 | H27: 10 | I27: 8 | J27: 110 | K27: 10 | L27: =SUM(K27,I27,H27,G27)+J27/3 -> 73.666667 | M27: =IF(ISERROR(L27),"",L27) -> 73.666667 | N27: =IF(M27="","",IF(M27>=$Q$3,$P$3,IF(M27>=$Q$4,$P$4,IF(M27>=$Q$5,$P$5,"P")))) -> PR
A28: Faiz, Meraj | B28: 104350 | C28: 24036465 | D28: maf239 | E28: yale.instructure.com | F28: MGT 404 01 | G28: 9.5 | H28: 10 | I28: 10 | J28: =VLOOKUP(C28,exam!$D$29:$V$359,19,0) -> 133.5 | K28: 10 | L28: =SUM(K28,I28,H28,G28)+J28/3 -> 84 | M28: =IF(ISERROR(L28),"",L28) -> 84 | N28: =IF(M28="","",IF(M28>=$Q$3,$P$3,IF(M28>=$Q$4,$P$4,IF(M28>=$Q$5,$P$5,"P")))) -> PR
A29: Feng, Charlie | B29: 112891 | C29: 24168861 | D29: csf27 | E29: yale.instructure.com | F29: MGT 404 01 | G29: 9 | H29: 10 | I29: 10 | J29: =VLOOKUP(C29,exam!$D$29:$V$359,19,0) -> 155 | K29: 10 | L29: =SUM(K29,I29,H29,G29)+J29/3 -> 90.666667 | M29: =IF(ISERROR(L29),"",L29) -> 90.666667 | N29: =IF(M29="","",IF(M29>=$Q$3,$P$3,IF(M29>=$Q$4,$P$4,IF(M29>=$Q$5,$P$5,"P")))) -> H
A30: Frederick, Julia | B30: 107776 | C30: 24089624 | D30: jkf43 | E30: yale.instructure.com | F30: MGT 404 01 | G30: 8 | H30: 9 | I30: 10 | J30: =VLOOKUP(C30,exam!$D$29:$V$359,19,0) -> 122.5 | K30: 10 | L30: =SUM(K30,I30,H30,G30)+J30/3 -> 77.833333 | M30: =IF(ISERROR(L30),"",L30) -> 77.833333 | N30: =IF(M30="","",IF(M30>=$Q$3,$P$3,IF(M30>=$Q$4,$P$4,IF(M30>=$Q$5,$P$5,"P")))) -> PR
A31: Freedman, Emily | B31: 111477 | C31: 24149192 | D31: erf39 | E31: yale.instructure.com | F31: MGT 404 01 | G31: 9 | H31: 8.75 | I31: 10 | J31: =VLOOKUP(C31,exam!$D$29:$V$359,19,0) -> 100 | K31: 10 | L31: =SUM(K31,I31,H31,G31)+J31/3 -> 71.083333 | M31: =IF(ISERROR(L31),"",L31) -> 71.083333 | N31: =IF(M31="","",IF(M31>=$Q$3,$P$3,IF(M31>=$Q$4,$P$4,IF(M31>=$Q$5,$P$5,"P")))) -> PR
A32: Glenn, Carey | B32: 86879 | C32: 17533290 | D32: ccg47 | E32: yale.instructure.com | F32: MGT 404 01 | G32: 9 | H32: 10 | I32: 10 | J32: =VLOOKUP(C32,exam!$D$29:$V$359,19,0) -> 122.5 | K32: 10 | L32: =SUM(K32,I32,H32,G32)+J32/3 -> 79.833333 | M32: =IF(ISERROR(L32),"",L32) -> 79.833333 | N32: =IF(M32="","",IF(M32>=$Q$3,$P$3,IF(M32>=$Q$4,$P$4,IF(M32>=$Q$5,$P$5,"P")))) -> PR
A33: Goldberg, Jonathan | B33: 113614 | C33: 24178194 | D33: jzg22 | E33: yale.instructure.com | F33: MGT 404 01 | G33: 7.5 | H33: 8.25 | I33: 9.8 | J33: =VLOOKUP(C33,exam!$D$29:$V$359,19,0) -> 122 | K33: 10 | L33: =SUM(K33,I33,H33,G33)+J33/3 -> 76.216667 | M33: =IF(ISERROR(L33),"",L33) -> 76.216667 | N33: =IF(M33="","",IF(M33>=$Q$3,$P$3,IF(M33>=$Q$4,$P$4,IF(M33>=$Q$5,$P$5,"P")))) -> PR
A34: Goldstein, Will | B34: 91751 | C34: 17594269 | D34: wrg24 | E34: yale.instructure.com | F34: MGT 404 01 | G34: 0 | I34: 0 | J34: =VLOOKUP(C34,exam!$D$29:$V$359,19,0) -> #N/A | K34: 10 | L34: =SUM(K34,I34,H34,G34)+J34/3 -> #N/A | M34: =IF(ISERROR(L34),"",L34) | N34: =IF(M34="","",IF(M34>=$Q$3,$P$3,IF(M34>=$Q$4,$P$4,IF(M34>=$Q$5,$P$5,"P"))))
A35: Grace-Flood, Liam | B35: 62265 | C35: 14312645 | D35: lag49 | E35: yale.instructure.com | F35: MGT 404 01 | G35: 0 | I35: 0 | J35: =VLOOKUP(C35,exam!$D$29:$V$359,19,0) -> #N/A | K35: 10 | L35: =SUM(K35,I35,H35,G35)+J35/3 -> #N/A | M35: =IF(ISERROR(L35),"",L35) | N35: =IF(M35="","",IF(M35>=$Q$3,$P$3,IF(M35>=$Q$4,$P$4,IF(M35>=$Q$5,$P$5,"P"))))
A36: Gu, Jeffrey | B36: 81908 | C36: 17460734 | D36: jg2528 | E36: yale.instructure.com | F36: MGT 404 01 | G36: 0 | I36: 0 | J36: =VLOOKUP(C36,exam!$D$29:$V$359,19,0) -> #N/A | K36: 10 | L36: =SUM(K36,I36,H36,G36)+J36/3 -> #N/A | M36: =IF(ISERROR(L36),"",L36) | N36: =IF(M36="","",IF(M36>=$Q$3,$P$3,IF(M36>=$Q$4,$P$4,IF(M36>=$Q$5,$P$5,"P"))))
A37: Gurjar, Madhura | B37: 111737 | C37: 24151198 | D37: msg69 | E37: yale.instructure.com | F37: MGT 404 01 | G37: 9 | H37: 9.5 | I37: 10 | J37: =VLOOKUP(C37,exam!$D$29:$V$359,19,0) -> 122.5 | K37: 10 | L37: =SUM(K37,I37,H37,G37)+J37/3 -> 79.333333 | M37: =IF(ISERROR(L37),"",L37) -> 79.333333 | N37: =IF(M37="","",IF(M37>=$Q$3,$P$3,IF(M37>=$Q$4,$P$4,IF(M37>=$Q$5,$P$5,"P")))) -> PR
A38: Hallowell, Sarah | B38: 87806 | C38: 17547723 | D38: sbh42 | E38: yale.instructure.com | F38: MGT 404 01 | G38: 0 | I38: 0 | J38: =VLOOKUP(C38,exam!$D$29:$V$359,19,0) -> #N/A | K38: 10 | L38: =SUM(K38,I38,H38,G38)+J38/3 -> #N/A | M38: =IF(ISERROR(L38),"",L38) | N38: =IF(M38="","",IF(M38>=$Q$3,$P$3,IF(M38>=$Q$4,$P$4,IF(M38>=$Q$5,$P$5,"P"))))
A39: Harris, Eric | B39: 112206 | C39: 24158423 | D39: erh52 | E39: yale.instructure.com | F39: MGT 404 01 | G39: 9 | H39: 9 | I39: 9.8 | J39: =VLOOKUP(C39,exam!$D$29:$V$359,19,0) -> 166.5 | K39: 10 | L39: =SUM(K39,I39,H39,G39)+J39/3 -> 93.3 | M39: =IF(ISERROR(L39),"",L39) -> 93.3 | N39: =IF(M39="","",IF(M39>=$Q$3,$P$3,IF(M39>=$Q$4,$P$4,IF(M39>=$Q$5,$P$5,"P")))) -> HH
A40: Haydock, Ben | B40: 108803 | C40: 24105247 | D40: brh37 | E40: yale.instructure.com | F40: MGT 404 01 | G40: 10 | H40: 9.75 | I40: 10 | J40: =VLOOKUP(C40,exam!$D$29:$V$359,19,0) -> 138 | K40: 10 | L40: =SUM(K40,I40,H40,G40)+J40/3 -> 85.75 | M40: =IF(ISERROR(L40),"",L40) -> 85.75 | N40: =IF(M40="","",IF(M40>=$Q$3,$P$3,IF(M40>=$Q$4,$P$4,IF(M40>=$Q$5,$P$5,"P")))) -> H
...

Sheet csv
A1: Student | B1: ID | C1: SIS User ID | D1: SIS Login ID | E1: Root Account | F1: Section | G1: Final Exam (125495)
A3: Points Possible | G3: 180
A4: Yazarov, Maxim | B4: 107311 | C4: 24080903 | D4: my397 | E4: yale.instructure.com | F4: MGT 404 03 | G4: 42.5
A5: Danielson, Katherine | B5: 107593 | C5: 24086258 | D5: ked59 | E5: yale.instructure.com | F5: MGT 404 05 | G5: 51
A6: Bader, Lindsay | B6: 109628 | C6: 24119612 | D6: lb967 | E6: yale.instructure.com | F6: MGT 404 04 | G6: 61
A7: Johnson, Nicholas | B7: 113847 | C7: 24182308 | D7: nj259 | E7: yale.instructure.com | F7: MGT 404 04 | G7: 62
A8: Hines, Daven | B8: 109871 | C8: 24122910 | D8: dh763 | E8: yale.instructure.com | F8: MGT 404 02 | G8: 67
A9: Orchingwa, Uzoma | B9: 33901 | C9: 15904474 | D9: uo23 | E9: yale.instructure.com | F9: MGT 404 03 | G9: 73.5
A10: Sharma, Vipul | B10: 104099 | C10: 24012359 | D10: vs427 | E10: yale.instructure.com | F10: MGT 404 01 | G10: 74
A11: Kacyem, Lina | B11: 104341 | C11: 24036159 | D11: lgk7 | E11: yale.instructure.com | F11: MGT 404 04 | G11: 76
A12: Boyajian, Ann | B12: 104517 | C12: 24036261 | D12: kam333 | E12: yale.instructure.com | F12: MGT 404 03 | G12: 79
A13: Feliz, Kiara | B13: 109908 | C13: 24122689 | D13: kf522 | E13: yale.instructure.com | F13: MGT 404 05 | G13: 79
A14: Lewis, Christian | B14: 104048 | C14: 24037536 | D14: cwl42 | E14: yale.instructure.com | F14: MGT 404 03 | G14: 80
A15: Park, Iris | B15: 109996 | C15: 24124338 | D15: ihp4 | E15: yale.instructure.com | F15: MGT 404 03 | G15: 80
... A334: Zhou, Shengshun | B334: 109124 | C334: 24111010 | D334: sz428 | E334: yale.instructure.com | F334: MGT 404 05 | G334: 176.5

Sheet exam
I1: Short Answer (Out of 10) | O1: Long Answer | V1: TOTAL
B2: Agarwal, Vibhav | C2: 87811 | D2: 17547995 | E2: va256 | F2: yale.instructure.com | G2: MGT 404 01 | H2: 1 | V2: 0
B3: Briggi, Danny | C3: 91806 | D3: 17595782 | E3: db2263 | F3: yale.instructure.com | G3: MGT 404 01 | H3: 1 | V3: 0
B4: Cisneros, Tony | C4: 82127 | D4: 17469744 | E4: ac2764 | F4: yale.instructure.com | G4: MGT 404 01 | H4: 1 | V4: 0
B5: Desai, Keval | C5: 17638 | D5: 15880589 | E5: knd22 | F5: yale.instructure.com | G5: MGT 404 01 | H5: 1 | V5: 0
B6: Doshi, Pooja | C6: 82016 | D6: 17469812 | E6: prd26 | F6: yale.instructure.com | G6: MGT 404 01 | H6: 1 | V6: 0
B7: Edelman, AJ | C7: 111140 | D7: 24143684 | E7: aje46 | F7: yale.instructure.com | G7: MGT 404 01 | V7: 110
B8: Goldstein, Will | C8: 91751 | D8: 17594269 | E8: wrg24 | F8: yale.instructure.com | G8: MGT 404 01 | H8: 1 | V8: 0
B9: Grace-Flood, Liam | C9: 62265 | D9: 14312645 | E9: lag49 | F9: yale.instructure.com | G9: MGT 404 01 | H9: 1 | V9: 0
B10: Gu, Jeffrey | C10: 81908 | D10: 17460734 | E10: jg2528 | F10: yale.instructure.com | G10: MGT 404 01 | H10: 1 | V10: 0
B11: Hallowell, Sarah | C11: 87806 | D11: 17547723 | E11: sbh42 | F11: yale.instructure.com | G11: MGT 404 01 | H11: 1 | V11: 0
B12: Madden, Drew | C12: 58753 | D12: 17221102 | E12: ddm44 | F12: yale.instructure.com | G12: MGT 404 01 | H12: 1 | V12: 0
B13: Millham, Sam | C13: 82200 | D13: 17460547 | E13: spm59 | F13: yale.instructure.com | G13: MGT 404 01 | H13: 1 | V13: 0
B14: Monge Kaser, Samantha | C14: 35712 | D14: 13415895 | E14: slm86 | F14: yale.instructure.com | G14: MGT 404 01 | H14: 1 | V14: 0
B15: Mullen, Tony | C15: 82161 | D15: 17469013 | E15: ajm258 | F15: yale.instructure.com | G15: MGT 404 01 | H15: 1 | V15: 0
B16: Pellakuru, Chak | C16: 84506 | D16: 17501857 | E16: cp843 | F16: yale.instructure.com | G16: MGT 404 01 | H16: 1 | V16: 0
B17: Peranzi, Nick | C17: 84930 | D17: 17508062 | E17: njp37 | F17: yale.instructure.com | G17: MGT 404 01 | H17: 1 | V17: 0
B18: Ra, Thu | C18: 82381 | D18: 17470254 | E18: tr394 | F18: yale.instructure.com | G18: MGT 404 01 | H18: 1 | V18: 0
B19: Scott, Sidney | C19: 90604 | D19: 17585956 | E19: ss3785 | F19: yale.instructure.com | G19: MGT 404 01 | H19: 1 | V19: 0
... B26: Zhao, Jack | C26: 29412 | D26: 13469309 | E26: oz4 | F26: yale.instructure.com | G26: MGT 404 01 | H26: 1 | V26: 0
B27: McGovern, Patrick | C27: 110101 | D27: 12418114 | E27: pwm24 | F27: yale.instructure.com | G27: MGT 404 02 | V27: 111
B28: Burnette, Blake | C28: 113478 | D28: 24176443 | E28: bjb78 | F28: yale.instructure.com | G28: MGT 404 04 | V28: 148
B29: Yazarov, Maxim | C29: 107311 | D29: 24080903 | E29: my397 | F29: yale.instructure.com | G29: MGT 404 03 | I29: 0 | J29: 0 | K29: 5 | L29: 5 | M29: 0 | N29: 10 | O29: 0 | P29: 0 | Q29: 16 | R29: 6.5 | S29: 0 | T29: 0 | U29: 0 | V29: 42.5
B30: Danielson, Katherine | C30: 107593 | D30: 24086258 | E30: ked59 | F30: yale.instructure.com | G30: MGT 404 05 | I30: 5 | J30: 0 | K30: 5 | L30: 5 | M30: 0 | N30: 2 | O30: 4 | P30: 0 | Q30: 8 | R30: 6 | S30: 3 | T30: 10 | U30: 3 | V30: 51
B31: Bader, Lindsay | C31: 109628 | D31: 24119612 | E31: lb967 | F31: yale.instructure.com | G31: MGT 404 04 | I31: 5 | J31: 5 | K31: 0 | L31: 0 | M31: 5 | N31: 0 | O31: 2 | P31: 11 | Q31: 14 | R31: 6 | S31: 4 | T31: 8 | U31: 1 | V31: 61
B32: Johnson, Nicholas | C32: 113847 | D32: 24182308 | E32: nj259 | F32: yale.instructure.com | G32: MGT 404 04 | I32: 10 | J32: 2 | K32: 0 | L32: 5 | M32: 5 | N32: 0 | O32: 0 | P32: 10 | Q32: 5 | R32: 12 | S32: 2 | T32: 6 | U32: 5 | V32: 62
B33: Hines, Daven | C33: 109871 | D33: 24122910 | E33: dh763 | F33: yale.instructure.com | G33: MGT 404 02 | I33: 5 | J33: 10 | K33: 0 | L33: 5 | M33: 0 | N33: 2 | O33: 5 | P33: 14 | Q33: 11 | R33: 6 | S33: 9 | T33: 0 | U33: 0 | V33: 67
B34: Orchingwa, Uzoma | C34: 33901 | D34: 15904474 | E34: uo23 | F34: yale.instructure.com | G34: MGT 404 03 | I34: 5 | J34: 0 | K34: 0 | L34: 0 | M34: 0 | N34: 5 | O34: 4 | P34: 10 | Q34: 12 | R34: 3.5 | S34: 5 | T34: 25 | U34: 4 | V34: 73.5
B35: Sharma, Vipul | C35: 104099 | D35: 24012359 | E35: vs427 | F35: yale.instructure.com | G35: MGT 404 01 | I35: 5 | J35: 7 | K35: 5 | L35: 5 | M35: 5 | N35: 0 | O35: 1 | P35: 10 | Q35: 12 | R35: 10 | S35: 4 | T35: 10 | U35: 0 | V35: 74
B36: Kacyem, Lina | C36: 104341 | D36: 24036159 | E36: lgk7 | F36: yale.instructure.com | G36: MGT 404 04 | I36: 10 | J36: 5 | K36: 0 | L36: 5 | M36: 5 | N36: 2 | O36: 5 | P36: 10 | Q36: 16 | R36: 9 | S36: 2 | T36: 4 | U36: 3 | V36: 76
B37: Boyajian, Ann | C37: 104517 | D37: 24036261 | E37: kam333 | F37: yale.instructure.com | G37: MGT 404 03 | I37: 10 | J37: 5 | K37: 0 | L37: 5 | M37: 10 | N37: 2 | O37: 5 | P37: 8 | Q37: 7 | R37: 6 | S37: 6 | T37: 9 | U37: 6 | V37: 79
B38: Feliz, Kiara | C38: 109908 | D38: 24122689 | E38: kf522 | F38: yale.instructure.com | G38: MGT 404 05 | I38: 0 | J38: 5 | K38: 5 | L38: 10 | M38: 0 | N38: 0 | O38: 5 | P38: 16 | Q38: 7 | R38: 3 | S38: 1 | T38: 12 | U38: 15 | V38: 79
B39: Lewis, Christian | C39: 104048 | D39: 24037536 | E39: cwl42 | F39: yale.instructure.com | G39: MGT 404 03 | I39: 10 | J39: 0 | K39: 10 | L39: 5 | M39: 10 | N39: 5 | O39: 5 | P39: 12 | Q39: 7 | R39: 6 | S39: 0 | T39: 8 | U39: 2 | V39: 80
B40: Park, Iris | C40: 109996 | D40: 24124338 | E40: ihp4 | F40: yale.instructure.com | G40: MGT 404 03 | I40: 0 | J40: 5 | K40: 10 | L40: 5 | M40: 0 | N40: 10 | O40: 5 | P40: 14 | Q40: 15 | R40: 13 | S40: 2 | T40: 0 | U40: 1 | V40: 80
... B359: Zhou, Shengshun | C359: 109124 | D359: 24111010 | E359: sz428 | F359: yale.instructure.com | G359: MGT 404 05 | I359: 5 | J359: 10 | K359: 10 | L359: 10 | M359: 10 | N359: 10 | O359: 16 | P359: 18 | Q359: 16 | R359: 15.5 | S359: 16 | T359: 25 | U359: 15 | V359: 176.5
B360: Student | C360: ID | D360: SIS User ID | E360: SIS Login ID | F360: Root Account | G360: Section | H360: Second Year | I360: Q1 | J360: Q2 | K360: Q3 | L360: Q4 | M360: Q5 | N360: Q6 | O360: Q1 (16) | P360: Q2 (16) | Q360: Q3 (16) | R360: Q4 (16) | S360: Q5 (16) | T360: Q6 (25) | U360: Q7 (15) | V360: -180
B362: 335 | C362: 335 | D362: 335 | E362: 335 | F362: 335 | H362: 23 | I362: 332 | J362: 332 | K362: 332 | L362: 332 | M362: 332 | N362: 332 | O362: 332 | P362: 332 | Q362: 332 | R362: 332 | S362: 332 | T362: 332 | U362: 332 | V362: 129.7719
I363: 0.99 | J363: 0.99 | K363: 0.99 | L363: 0.99 | M363: 0.99 | N363: 0.99 | O363: 0.99 | P363: 0.99 | Q363: 0.99 | R363: 0.99 | S363: 0.99 | T363: 0.99 | U363: 0.99 | V363: 24.540537
I365: =AVERAGE(I29:I359) -> 7.2265861 | J365: =AVERAGE(J29:J359) -> 6.0664653 | K365: =AVERAGE(K29:K359) -> 6.4954683 | L365: =AVERAGE(L29:L359) -> 4.6072508 | M365: =AVERAGE(M29:M359) -> 5.8308157 | N365: =AVERAGE(N29:N359) -> 7.1238671 | O365: =AVERAGE(O29:O359) -> 10.217523 | P365: =AVERAGE(P29:P359) -> 14.719033 | ... U365: =AVERAGE(U29:U359) -> 7.6586103
